(base) rruiz@dual-rtx-4090s:/mnt/DATA01/include/www.deepily.ai/projects$ SDPEFT 8888 0.2.0 `pwd`
peft
Starting docker peft on port [8888] w/ image version [0.2.0] from [/mnt/DATA01/include/www.deepily.ai/projects]...

After Docker starts, run this: [jupyter lab --ip=0.0.0.0 --allow-root --port 3000]
root@fe0dd39a6dac:/# cd /var/model/lupin/src/
root@fe0dd39a6dac:/var/model/lupin/src# ll
total 92
drwxr--r-- 11 1001 1001  4096 Oct  8 15:04 ./
drwxr--r-- 12 1001 1001  4096 Oct  6 03:53 ../
-rwxr--r--  1 1001 1001  8196 Feb 27  2024 .DS_Store*
-rwxr--r--  1 1001 1001  4096 Mar 21  2023 ._.DS_Store*
-rwxr--r--  1 1001 1001  4096 Sep 15 15:56 ._app.py*
drwxr--r--  3 1001 1001  4096 Mar 21  2023 .idea/
drwxr--r--  2 1001 1001  4096 Oct  4 02:07 __pycache__/
-rw-rw-r--  1 1001 1001 25777 Oct  4 02:07 app.py
drwxr--r--  6 1001 1001  4096 Oct  8 21:55 conf/
drwxr--r--  6 1001 1001  4096 Feb 16  2024 ephemera/
drwxr--r-- 11 1001 1001  4096 Oct  6 01:56 lib/
drwxr--r--  3 1001 1001  4096 Mar 10  2023 resources/
drwxr-xr-x  2 1001 1001  4096 Jan 24  2024 scripts/
drwxr--r--  2 1001 1001  4096 Nov 20  2023 static/
drwxr--r--  2 1001 1001  4096 Sep 26  2023 templates/
root@fe0dd39a6dac:/var/model/lupin/src# H export GENIE_IN_THE_BOX_ROOT=/var/model/lupin
root@4701293be064:/var/model/lupin/src# python3 -m ephemera.notebooks.cosa.gsm8k
bash: H: command not found
bash: root@4701293be064:/var/model/lupin/src#: No such file or directory
root@fe0dd39a6dac:/var/model/lupin/src# ^C
root@fe0dd39a6dac:/var/model/lupin/src# env
NVIDIA_VISIBLE_DEVICES=all
HOSTNAME=fe0dd39a6dac
NVIDIA_REQUIRE_CUDA=cuda>=12.2 brand=tesla,driver>=470,driver<471 brand=unknown,driver>=470,driver<471 brand=nvidia,driver>=470,driver<471 brand=nvidiartx,driver>=470,driver<471 brand=geforce,driver>=470,driver<471 brand=geforcertx,driver>=470,driver<471 brand=quadro,driver>=470,driver<471 brand=quadrortx,driver>=470,driver<471 brand=titan,driver>=470,driver<471 brand=titanrtx,driver>=470,driver<471 brand=tesla,driver>=525,driver<526 brand=unknown,driver>=525,driver<526 brand=nvidia,driver>=525,driver<526 brand=nvidiartx,driver>=525,driver<526 brand=geforce,driver>=525,driver<526 brand=geforcertx,driver>=525,driver<526 brand=quadro,driver>=525,driver<526 brand=quadrortx,driver>=525,driver<526 brand=titan,driver>=525,driver<526 brand=titanrtx,driver>=525,driver<526
PWD=/var/model/lupin/src
NVIDIA_DRIVER_CAPABILITIES=compute,utility
NV_CUDA_CUDART_VERSION=12.2.140-1
HOME=/root
LS_COLORS=rs=0:di=01;34:ln=01;36:mh=00:pi=40;33:so=01;35:do=01;35:bd=40;33;01:cd=40;33;01:or=40;31;01:mi=00:su=37;41:sg=30;43:ca=30;41:tw=30;42:ow=34;42:st=37;44:ex=01;32:*.tar=01;31:*.tgz=01;31:*.arc=01;31:*.arj=01;31:*.taz=01;31:*.lha=01;31:*.lz4=01;31:*.lzh=01;31:*.lzma=01;31:*.tlz=01;31:*.txz=01;31:*.tzo=01;31:*.t7z=01;31:*.zip=01;31:*.z=01;31:*.dz=01;31:*.gz=01;31:*.lrz=01;31:*.lz=01;31:*.lzo=01;31:*.xz=01;31:*.zst=01;31:*.tzst=01;31:*.bz2=01;31:*.bz=01;31:*.tbz=01;31:*.tbz2=01;31:*.tz=01;31:*.deb=01;31:*.rpm=01;31:*.jar=01;31:*.war=01;31:*.ear=01;31:*.sar=01;31:*.rar=01;31:*.alz=01;31:*.ace=01;31:*.zoo=01;31:*.cpio=01;31:*.7z=01;31:*.rz=01;31:*.cab=01;31:*.wim=01;31:*.swm=01;31:*.dwm=01;31:*.esd=01;31:*.jpg=01;35:*.jpeg=01;35:*.mjpg=01;35:*.mjpeg=01;35:*.gif=01;35:*.bmp=01;35:*.pbm=01;35:*.pgm=01;35:*.ppm=01;35:*.tga=01;35:*.xbm=01;35:*.xpm=01;35:*.tif=01;35:*.tiff=01;35:*.png=01;35:*.svg=01;35:*.svgz=01;35:*.mng=01;35:*.pcx=01;35:*.mov=01;35:*.mpg=01;35:*.mpeg=01;35:*.m2v=01;35:*.mkv=01;35:*.webm=01;35:*.webp=01;35:*.ogm=01;35:*.mp4=01;35:*.m4v=01;35:*.mp4v=01;35:*.vob=01;35:*.qt=01;35:*.nuv=01;35:*.wmv=01;35:*.asf=01;35:*.rm=01;35:*.rmvb=01;35:*.flc=01;35:*.avi=01;35:*.fli=01;35:*.flv=01;35:*.gl=01;35:*.dl=01;35:*.xcf=01;35:*.xwd=01;35:*.yuv=01;35:*.cgm=01;35:*.emf=01;35:*.ogv=01;35:*.ogx=01;35:*.aac=00;36:*.au=00;36:*.flac=00;36:*.m4a=00;36:*.mid=00;36:*.midi=00;36:*.mka=00;36:*.mp3=00;36:*.mpc=00;36:*.ogg=00;36:*.ra=00;36:*.wav=00;36:*.oga=00;36:*.opus=00;36:*.spx=00;36:*.xspf=00;36:
CUDA_VERSION=12.2.2
LESSCLOSE=/usr/bin/lesspipe %s %s
TERM=xterm
LESSOPEN=| /usr/bin/lesspipe %s
SHLVL=1
NVARCH=x86_64
NV_CUDA_COMPAT_PACKAGE=cuda-compat-12-2
LD_LIBRARY_PATH=/usr/local/nvidia/lib:/usr/local/nvidia/lib64
PATH=/usr/local/nvidia/bin:/usr/local/cuda/bin:/usr/local/sbin:/usr/local/bin:/usr/sbin:/usr/bin:/sbin:/bin
OLDPWD=/
_=/usr/bin/env
root@fe0dd39a6dac:/var/model/lupin/src# echo $GENIE_IN_THE_BOX_ROOT

root@fe0dd39a6dac:/var/model/lupin/src# export GENIE_IN_THE_BOX_ROOT=/var/model/lupin
root@fe0dd39a6dac:/var/model/lupin/src# echo $GENIE_IN_THE_BOX_ROOT
/var/model/lupin
root@fe0dd39a6dac:/var/model/lupin/src# echo $GENIE_IN_THE_BOX_ROOT
/var/model/lupin
root@fe0dd39a6dac:/var/model/lupin/src# python3 -m ephemera.notebooks.cosa.gsm8k
Traceback (most recent call last):
  File "/usr/lib/python3.10/runpy.py", line 196, in _run_module_as_main
    return _run_code(code, main_globals, None,
  File "/usr/lib/python3.10/runpy.py", line 86, in _run_code
    exec(code, run_globals)
  File "/var/model/lupin/src/ephemera/notebooks/cosa/gsm8k.py", line 9, in <module>
    from lib.agents.math_agent           import MathAgent
  File "/var/model/lupin/src/lib/agents/math_agent.py", line 6, in <module>
    from lib.agents.llm                  import Llm
  File "/var/model/lupin/src/lib/agents/llm.py", line 7, in <module>
    from groq                       import Groq
ModuleNotFoundError: No module named 'groq'
root@fe0dd39a6dac:/var/model/lupin/src# ^C
root@fe0dd39a6dac:/var/model/lupin/src# ll /var/model/benchmarks/gsm8k/
total 2756
drwxrwxr-x 2 1001 1001    4096 Oct  9 02:43 ./
drwxrwxr-x 3 1001 1001    4096 Oct  6 17:50 ../
-rw-r--r-- 1 root root   74719 Oct  8 16:29 results-2024-10-08-at-12-29-30-tgi-phind-codellama-34b-v2.csv
-rw-r--r-- 1 root root    4033 Oct  9 02:43 results-2024-10-08-at-22-43-30-groq-llama-3.1-8b-instant.csv
-rwxr--r-- 1 1001 1001  419088 Oct  6 17:51 test-00000-of-00001.parquet*
-rwxr--r-- 1 1001 1001 2306545 Oct  6 17:51 train-00000-of-00001.parquet*
root@fe0dd39a6dac:/var/model/lupin/src# ll /var/model/benchmarks/gsm8k/results*groq*3.1*.csv
-rw-r--r-- 1 root root 4033 Oct  9 02:43 /var/model/benchmarks/gsm8k/results-2024-10-08-at-22-43-30-groq-llama-3.1-8b-instant.csv
root@fe0dd39a6dac:/var/model/lupin/src# rm /var/model/benchmarks/gsm8k/results*groq*3.1-8b*.csv
root@fe0dd39a6dac:/var/model/lupin/src# ll /var/model/benchmarks/gsm8k/results*groq*3.1*.csv
ls: cannot access '/var/model/benchmarks/gsm8k/results*groq*3.1*.csv': No such file or directory
root@fe0dd39a6dac:/var/model/lupin/src# ll /var/model/benchmarks/gsm8k/
total 2752
drwxrwxr-x 2 1001 1001    4096 Oct  9 15:20 ./
drwxrwxr-x 3 1001 1001    4096 Oct  6 17:50 ../
-rw-r--r-- 1 root root   74719 Oct  8 16:29 results-2024-10-08-at-12-29-30-tgi-phind-codellama-34b-v2.csv
-rwxr--r-- 1 1001 1001  419088 Oct  6 17:51 test-00000-of-00001.parquet*
-rwxr--r-- 1 1001 1001 2306545 Oct  6 17:51 train-00000-of-00001.parquet*
root@fe0dd39a6dac:/var/model/lupin/src# mkdir /var/model/benchmarks/gsm8k/checkpoints
root@fe0dd39a6dac:/var/model/lupin/src# python3 -m ephemera.notebooks.cosa.gsm8k
Traceback (most recent call last):
  File "/usr/lib/python3.10/runpy.py", line 196, in _run_module_as_main
    return _run_code(code, main_globals, None,
  File "/usr/lib/python3.10/runpy.py", line 86, in _run_code
    exec(code, run_globals)
  File "/var/model/lupin/src/ephemera/notebooks/cosa/gsm8k.py", line 3, in <module>
    from sqlalchemy.sql.functions import current_date
ModuleNotFoundError: No module named 'sqlalchemy'
root@fe0dd39a6dac:/var/model/lupin/src# python3 -m ephemera.notebooks.cosa.gsm8k
Traceback (most recent call last):
  File "/usr/lib/python3.10/runpy.py", line 196, in _run_module_as_main
    return _run_code(code, main_globals, None,
  File "/usr/lib/python3.10/runpy.py", line 86, in _run_code
    exec(code, run_globals)
  File "/var/model/lupin/src/ephemera/notebooks/cosa/gsm8k.py", line 9, in <module>
    from lib.agents.math_agent           import MathAgent
  File "/var/model/lupin/src/lib/agents/math_agent.py", line 6, in <module>
    from lib.agents.llm                  import Llm
  File "/var/model/lupin/src/lib/agents/llm.py", line 7, in <module>
    from groq                       import Groq
ModuleNotFoundError: No module named 'groq'
root@fe0dd39a6dac:/var/model/lupin/src# pip install groq
Collecting groq
  Downloading groq-0.11.0-py3-none-any.whl.metadata (13 kB)
Requirement already satisfied: anyio<5,>=3.5.0 in /usr/local/lib/python3.10/dist-packages (from groq) (4.2.0)
Requirement already satisfied: distro<2,>=1.7.0 in /usr/local/lib/python3.10/dist-packages (from groq) (1.9.0)
Requirement already satisfied: httpx<1,>=0.23.0 in /usr/local/lib/python3.10/dist-packages (from groq) (0.26.0)
Requirement already satisfied: pydantic<3,>=1.9.0 in /usr/local/lib/python3.10/dist-packages (from groq) (2.5.3)
Requirement already satisfied: sniffio in /usr/local/lib/python3.10/dist-packages (from groq) (1.3.0)
Requirement already satisfied: typing-extensions<5,>=4.7 in /usr/local/lib/python3.10/dist-packages (from groq) (4.9.0)
Requirement already satisfied: idna>=2.8 in /usr/local/lib/python3.10/dist-packages (from anyio<5,>=3.5.0->groq) (3.6)
Requirement already satisfied: exceptiongroup>=1.0.2 in /usr/local/lib/python3.10/dist-packages (from anyio<5,>=3.5.0->groq) (1.2.0)
Requirement already satisfied: certifi in /usr/local/lib/python3.10/dist-packages (from httpx<1,>=0.23.0->groq) (2023.11.17)
Requirement already satisfied: httpcore==1.* in /usr/local/lib/python3.10/dist-packages (from httpx<1,>=0.23.0->groq) (1.0.2)
Requirement already satisfied: h11<0.15,>=0.13 in /usr/local/lib/python3.10/dist-packages (from httpcore==1.*->httpx<1,>=0.23.0->groq) (0.14.0)
Requirement already satisfied: annotated-types>=0.4.0 in /usr/local/lib/python3.10/dist-packages (from pydantic<3,>=1.9.0->groq) (0.6.0)
Requirement already satisfied: pydantic-core==2.14.6 in /usr/local/lib/python3.10/dist-packages (from pydantic<3,>=1.9.0->groq) (2.14.6)
Downloading groq-0.11.0-py3-none-any.whl (106 kB)
   ━━━━━━━━━━━━━━━━━━━━━━━━━━━━━━━━━━━━━━━━ 106.5/106.5 kB 6.0 MB/s eta 0:00:00
Installing collected packages: groq
Successfully installed groq-0.11.0
WARNING: Running pip as the 'root' user can result in broken permissions and conflicting behaviour with the system package manager. It is recommended to use a virtual environment instead: https://pip.pypa.io/warnings/venv

[notice] A new release of pip is available: 23.3.2 -> 24.2
[notice] To update, run: python3 -m pip install --upgrade pip
root@fe0dd39a6dac:/var/model/lupin/src# python3 -m ephemera.notebooks.cosa.gsm8k
Traceback (most recent call last):
  File "/usr/lib/python3.10/runpy.py", line 196, in _run_module_as_main
    return _run_code(code, main_globals, None,
  File "/usr/lib/python3.10/runpy.py", line 86, in _run_code
    exec(code, run_globals)
  File "/var/model/lupin/src/ephemera/notebooks/cosa/gsm8k.py", line 9, in <module>
    from lib.agents.math_agent           import MathAgent
  File "/var/model/lupin/src/lib/agents/math_agent.py", line 6, in <module>
    from lib.agents.llm                  import Llm
  File "/var/model/lupin/src/lib/agents/llm.py", line 9, in <module>
    import google.generativeai      as genai
ModuleNotFoundError: No module named 'google.generativeai'
root@fe0dd39a6dac:/var/model/lupin/src# pip install google.generativeai
Collecting google.generativeai
  Downloading google_generativeai-0.8.3-py3-none-any.whl.metadata (3.9 kB)
Collecting google-ai-generativelanguage==0.6.10 (from google.generativeai)
  Downloading google_ai_generativelanguage-0.6.10-py3-none-any.whl.metadata (5.6 kB)
Collecting google-api-core (from google.generativeai)
  Downloading google_api_core-2.21.0-py3-none-any.whl.metadata (2.8 kB)
Collecting google-api-python-client (from google.generativeai)
  Downloading google_api_python_client-2.149.0-py2.py3-none-any.whl.metadata (6.7 kB)
Collecting google-auth>=2.15.0 (from google.generativeai)
  Downloading google_auth-2.35.0-py2.py3-none-any.whl.metadata (4.7 kB)
Requirement already satisfied: protobuf in /usr/local/lib/python3.10/dist-packages (from google.generativeai) (4.25.1)
Requirement already satisfied: pydantic in /usr/local/lib/python3.10/dist-packages (from google.generativeai) (2.5.3)
Requirement already satisfied: tqdm in /usr/local/lib/python3.10/dist-packages (from google.generativeai) (4.66.1)
Requirement already satisfied: typing-extensions in /usr/local/lib/python3.10/dist-packages (from google.generativeai) (4.9.0)
Collecting proto-plus<2.0.0dev,>=1.22.3 (from google-ai-generativelanguage==0.6.10->google.generativeai)
  Downloading proto_plus-1.24.0-py3-none-any.whl.metadata (2.2 kB)
Collecting googleapis-common-protos<2.0.dev0,>=1.56.2 (from google-api-core->google.generativeai)
  Downloading googleapis_common_protos-1.65.0-py2.py3-none-any.whl.metadata (1.5 kB)
Requirement already satisfied: requests<3.0.0.dev0,>=2.18.0 in /usr/local/lib/python3.10/dist-packages (from google-api-core->google.generativeai) (2.31.0)
Requirement already satisfied: cachetools<6.0,>=2.0.0 in /usr/local/lib/python3.10/dist-packages (from google-auth>=2.15.0->google.generativeai) (5.3.2)
Collecting pyasn1-modules>=0.2.1 (from google-auth>=2.15.0->google.generativeai)
  Downloading pyasn1_modules-0.4.1-py3-none-any.whl.metadata (3.5 kB)
Collecting rsa<5,>=3.1.4 (from google-auth>=2.15.0->google.generativeai)
  Downloading rsa-4.9-py3-none-any.whl.metadata (4.2 kB)
Collecting httplib2<1.dev0,>=0.19.0 (from google-api-python-client->google.generativeai)
  Downloading httplib2-0.22.0-py3-none-any.whl.metadata (2.6 kB)
Collecting google-auth-httplib2<1.0.0,>=0.2.0 (from google-api-python-client->google.generativeai)
  Downloading google_auth_httplib2-0.2.0-py2.py3-none-any.whl.metadata (2.2 kB)
Collecting uritemplate<5,>=3.0.1 (from google-api-python-client->google.generativeai)
  Downloading uritemplate-4.1.1-py2.py3-none-any.whl.metadata (2.9 kB)
Requirement already satisfied: annotated-types>=0.4.0 in /usr/local/lib/python3.10/dist-packages (from pydantic->google.generativeai) (0.6.0)
Requirement already satisfied: pydantic-core==2.14.6 in /usr/local/lib/python3.10/dist-packages (from pydantic->google.generativeai) (2.14.6)
Collecting grpcio<2.0dev,>=1.33.2 (from google-api-core[grpc]!=2.0.*,!=2.1.*,!=2.10.*,!=2.2.*,!=2.3.*,!=2.4.*,!=2.5.*,!=2.6.*,!=2.7.*,!=2.8.*,!=2.9.*,<3.0.0dev,>=1.34.1->google-ai-generativelanguage==0.6.10->google.generativeai)
  Downloading grpcio-1.66.2-cp310-cp310-manylinux_2_17_x86_64.manylinux2014_x86_64.whl.metadata (3.9 kB)
Collecting grpcio-status<2.0.dev0,>=1.33.2 (from google-api-core[grpc]!=2.0.*,!=2.1.*,!=2.10.*,!=2.2.*,!=2.3.*,!=2.4.*,!=2.5.*,!=2.6.*,!=2.7.*,!=2.8.*,!=2.9.*,<3.0.0dev,>=1.34.1->google-ai-generativelanguage==0.6.10->google.generativeai)
  Downloading grpcio_status-1.66.2-py3-none-any.whl.metadata (1.1 kB)
Collecting pyparsing!=3.0.0,!=3.0.1,!=3.0.2,!=3.0.3,<4,>=2.4.2 (from httplib2<1.dev0,>=0.19.0->google-api-python-client->google.generativeai)
  Downloading pyparsing-3.1.4-py3-none-any.whl.metadata (5.1 kB)
Collecting pyasn1<0.7.0,>=0.4.6 (from pyasn1-modules>=0.2.1->google-auth>=2.15.0->google.generativeai)
  Downloading pyasn1-0.6.1-py3-none-any.whl.metadata (8.4 kB)
Requirement already satisfied: charset-normalizer<4,>=2 in /usr/local/lib/python3.10/dist-packages (from requests<3.0.0.dev0,>=2.18.0->google-api-core->google.generativeai) (3.3.2)
Requirement already satisfied: idna<4,>=2.5 in /usr/local/lib/python3.10/dist-packages (from requests<3.0.0.dev0,>=2.18.0->google-api-core->google.generativeai) (3.6)
Requirement already satisfied: urllib3<3,>=1.21.1 in /usr/local/lib/python3.10/dist-packages (from requests<3.0.0.dev0,>=2.18.0->google-api-core->google.generativeai) (2.1.0)
Requirement already satisfied: certifi>=2017.4.17 in /usr/local/lib/python3.10/dist-packages (from requests<3.0.0.dev0,>=2.18.0->google-api-core->google.generativeai) (2023.11.17)
Collecting protobuf (from google.generativeai)
  Downloading protobuf-5.28.2-cp38-abi3-manylinux2014_x86_64.whl.metadata (592 bytes)
Downloading google_generativeai-0.8.3-py3-none-any.whl (160 kB)
   ━━━━━━━━━━━━━━━━━━━━━━━━━━━━━━━━━━━━━━━━ 160.8/160.8 kB 4.2 MB/s eta 0:00:00
Downloading google_ai_generativelanguage-0.6.10-py3-none-any.whl (760 kB)
   ━━━━━━━━━━━━━━━━━━━━━━━━━━━━━━━━━━━━━━━━ 760.0/760.0 kB 39.7 MB/s eta 0:00:00
Downloading google_api_core-2.21.0-py3-none-any.whl (156 kB)
   ━━━━━━━━━━━━━━━━━━━━━━━━━━━━━━━━━━━━━━━━ 156.4/156.4 kB 55.8 MB/s eta 0:00:00
Downloading google_auth-2.35.0-py2.py3-none-any.whl (208 kB)
   ━━━━━━━━━━━━━━━━━━━━━━━━━━━━━━━━━━━━━━━━ 209.0/209.0 kB 64.0 MB/s eta 0:00:00
Downloading google_api_python_client-2.149.0-py2.py3-none-any.whl (12.3 MB)
   ━━━━━━━━━━━━━━━━━━━━━━━━━━━━━━━━━━━━━━━━ 12.3/12.3 MB 51.1 MB/s eta 0:00:00
Downloading google_auth_httplib2-0.2.0-py2.py3-none-any.whl (9.3 kB)
Downloading googleapis_common_protos-1.65.0-py2.py3-none-any.whl (220 kB)
   ━━━━━━━━━━━━━━━━━━━━━━━━━━━━━━━━━━━━━━━━ 220.9/220.9 kB 71.9 MB/s eta 0:00:00
Downloading httplib2-0.22.0-py3-none-any.whl (96 kB)
   ━━━━━━━━━━━━━━━━━━━━━━━━━━━━━━━━━━━━━━━━ 96.9/96.9 kB 31.7 MB/s eta 0:00:00
Downloading proto_plus-1.24.0-py3-none-any.whl (50 kB)
   ━━━━━━━━━━━━━━━━━━━━━━━━━━━━━━━━━━━━━━━━ 50.1/50.1 kB 16.1 MB/s eta 0:00:00
Downloading pyasn1_modules-0.4.1-py3-none-any.whl (181 kB)
   ━━━━━━━━━━━━━━━━━━━━━━━━━━━━━━━━━━━━━━━━ 181.5/181.5 kB 59.7 MB/s eta 0:00:00
Downloading rsa-4.9-py3-none-any.whl (34 kB)
Downloading uritemplate-4.1.1-py2.py3-none-any.whl (10 kB)
Downloading grpcio-1.66.2-cp310-cp310-manylinux_2_17_x86_64.manylinux2014_x86_64.whl (5.8 MB)
   ━━━━━━━━━━━━━━━━━━━━━━━━━━━━━━━━━━━━━━━━ 5.8/5.8 MB 44.6 MB/s eta 0:00:00
Downloading grpcio_status-1.66.2-py3-none-any.whl (14 kB)
Downloading protobuf-5.28.2-cp38-abi3-manylinux2014_x86_64.whl (316 kB)
   ━━━━━━━━━━━━━━━━━━━━━━━━━━━━━━━━━━━━━━━━ 316.6/316.6 kB 55.8 MB/s eta 0:00:00
Downloading pyasn1-0.6.1-py3-none-any.whl (83 kB)
   ━━━━━━━━━━━━━━━━━━━━━━━━━━━━━━━━━━━━━━━━ 83.1/83.1 kB 24.2 MB/s eta 0:00:00
Downloading pyparsing-3.1.4-py3-none-any.whl (104 kB)
   ━━━━━━━━━━━━━━━━━━━━━━━━━━━━━━━━━━━━━━━━ 104.1/104.1 kB 31.6 MB/s eta 0:00:00
Installing collected packages: uritemplate, pyparsing, pyasn1, protobuf, grpcio, rsa, pyasn1-modules, proto-plus, httplib2, googleapis-common-protos, grpcio-status, google-auth, google-auth-httplib2, google-api-core, google-api-python-client, google-ai-generativelanguage, google.generativeai
  Attempting uninstall: protobuf
    Found existing installation: protobuf 4.25.1
    Uninstalling protobuf-4.25.1:
      Successfully uninstalled protobuf-4.25.1
ERROR: pip's dependency resolver does not currently take into account all the packages that are installed. This behaviour is the source of the following dependency conflicts.
wandb 0.16.2 requires protobuf!=4.21.0,<5,>=3.19.0; python_version > "3.9" and sys_platform == "linux", but you have protobuf 5.28.2 which is incompatible.
Successfully installed google-ai-generativelanguage-0.6.10 google-api-core-2.21.0 google-api-python-client-2.149.0 google-auth-2.35.0 google-auth-httplib2-0.2.0 google.generativeai-0.8.3 googleapis-common-protos-1.65.0 grpcio-1.66.2 grpcio-status-1.66.2 httplib2-0.22.0 proto-plus-1.24.0 protobuf-5.28.2 pyasn1-0.6.1 pyasn1-modules-0.4.1 pyparsing-3.1.4 rsa-4.9 uritemplate-4.1.1
WARNING: Running pip as the 'root' user can result in broken permissions and conflicting behaviour with the system package manager. It is recommended to use a virtual environment instead: https://pip.pypa.io/warnings/venv

[notice] A new release of pip is available: 23.3.2 -> 24.2
[notice] To update, run: python3 -m pip install --upgrade pip
root@fe0dd39a6dac:/var/model/lupin/src# c
bash: c: command not found
root@fe0dd39a6dac:/var/model/lupin/src# clear
root@fe0dd39a6dac:/var/model/lupin/src# pip install google.generativeai
Requirement already satisfied: google.generativeai in /usr/local/lib/python3.10/dist-packages (0.8.3)
Requirement already satisfied: google-ai-generativelanguage==0.6.10 in /usr/local/lib/python3.10/dist-packages (from google.generativeai) (0.6.10)
Requirement already satisfied: google-api-core in /usr/local/lib/python3.10/dist-packages (from google.generativeai) (2.21.0)
Requirement already satisfied: google-api-python-client in /usr/local/lib/python3.10/dist-packages (from google.generativeai) (2.149.0)
Requirement already satisfied: google-auth>=2.15.0 in /usr/local/lib/python3.10/dist-packages (from google.generativeai) (2.35.0)
Requirement already satisfied: protobuf in /usr/local/lib/python3.10/dist-packages (from google.generativeai) (5.28.2)
Requirement already satisfied: pydantic in /usr/local/lib/python3.10/dist-packages (from google.generativeai) (2.5.3)
Requirement already satisfied: tqdm in /usr/local/lib/python3.10/dist-packages (from google.generativeai) (4.66.1)
Requirement already satisfied: typing-extensions in /usr/local/lib/python3.10/dist-packages (from google.generativeai) (4.9.0)
Requirement already satisfied: proto-plus<2.0.0dev,>=1.22.3 in /usr/local/lib/python3.10/dist-packages (from google-ai-generativelanguage==0.6.10->google.generativeai) (1.24.0)
Requirement already satisfied: googleapis-common-protos<2.0.dev0,>=1.56.2 in /usr/local/lib/python3.10/dist-packages (from google-api-core->google.generativeai) (1.65.0)
Requirement already satisfied: requests<3.0.0.dev0,>=2.18.0 in /usr/local/lib/python3.10/dist-packages (from google-api-core->google.generativeai) (2.31.0)
Requirement already satisfied: cachetools<6.0,>=2.0.0 in /usr/local/lib/python3.10/dist-packages (from google-auth>=2.15.0->google.generativeai) (5.3.2)
Requirement already satisfied: pyasn1-modules>=0.2.1 in /usr/local/lib/python3.10/dist-packages (from google-auth>=2.15.0->google.generativeai) (0.4.1)
Requirement already satisfied: rsa<5,>=3.1.4 in /usr/local/lib/python3.10/dist-packages (from google-auth>=2.15.0->google.generativeai) (4.9)
Requirement already satisfied: httplib2<1.dev0,>=0.19.0 in /usr/local/lib/python3.10/dist-packages (from google-api-python-client->google.generativeai) (0.22.0)
Requirement already satisfied: google-auth-httplib2<1.0.0,>=0.2.0 in /usr/local/lib/python3.10/dist-packages (from google-api-python-client->google.generativeai) (0.2.0)
Requirement already satisfied: uritemplate<5,>=3.0.1 in /usr/local/lib/python3.10/dist-packages (from google-api-python-client->google.generativeai) (4.1.1)
Requirement already satisfied: annotated-types>=0.4.0 in /usr/local/lib/python3.10/dist-packages (from pydantic->google.generativeai) (0.6.0)
Requirement already satisfied: pydantic-core==2.14.6 in /usr/local/lib/python3.10/dist-packages (from pydantic->google.generativeai) (2.14.6)
Requirement already satisfied: grpcio<2.0dev,>=1.33.2 in /usr/local/lib/python3.10/dist-packages (from google-api-core[grpc]!=2.0.*,!=2.1.*,!=2.10.*,!=2.2.*,!=2.3.*,!=2.4.*,!=2.5.*,!=2.6.*,!=2.7.*,!=2.8.*,!=2.9.*,<3.0.0dev,>=1.34.1->google-ai-generativelanguage==0.6.10->google.generativeai) (1.66.2)
Requirement already satisfied: grpcio-status<2.0.dev0,>=1.33.2 in /usr/local/lib/python3.10/dist-packages (from google-api-core[grpc]!=2.0.*,!=2.1.*,!=2.10.*,!=2.2.*,!=2.3.*,!=2.4.*,!=2.5.*,!=2.6.*,!=2.7.*,!=2.8.*,!=2.9.*,<3.0.0dev,>=1.34.1->google-ai-generativelanguage==0.6.10->google.generativeai) (1.66.2)
Requirement already satisfied: pyparsing!=3.0.0,!=3.0.1,!=3.0.2,!=3.0.3,<4,>=2.4.2 in /usr/local/lib/python3.10/dist-packages (from httplib2<1.dev0,>=0.19.0->google-api-python-client->google.generativeai) (3.1.4)
Requirement already satisfied: pyasn1<0.7.0,>=0.4.6 in /usr/local/lib/python3.10/dist-packages (from pyasn1-modules>=0.2.1->google-auth>=2.15.0->google.generativeai) (0.6.1)
Requirement already satisfied: charset-normalizer<4,>=2 in /usr/local/lib/python3.10/dist-packages (from requests<3.0.0.dev0,>=2.18.0->google-api-core->google.generativeai) (3.3.2)
Requirement already satisfied: idna<4,>=2.5 in /usr/local/lib/python3.10/dist-packages (from requests<3.0.0.dev0,>=2.18.0->google-api-core->google.generativeai) (3.6)
Requirement already satisfied: urllib3<3,>=1.21.1 in /usr/local/lib/python3.10/dist-packages (from requests<3.0.0.dev0,>=2.18.0->google-api-core->google.generativeai) (2.1.0)
Requirement already satisfied: certifi>=2017.4.17 in /usr/local/lib/python3.10/dist-packages (from requests<3.0.0.dev0,>=2.18.0->google-api-core->google.generativeai) (2023.11.17)
WARNING: Running pip as the 'root' user can result in broken permissions and conflicting behaviour with the system package manager. It is recommended to use a virtual environment instead: https://pip.pypa.io/warnings/venv

[notice] A new release of pip is available: 23.3.2 -> 24.2
[notice] To update, run: python3 -m pip install --upgrade pip
root@fe0dd39a6dac:/var/model/lupin/src# clear
root@fe0dd39a6dac:/var/model/lupin/src# python3 -m ephemera.notebooks.cosa.gsm8k
Traceback (most recent call last):
  File "/usr/lib/python3.10/runpy.py", line 196, in _run_module_as_main
    return _run_code(code, main_globals, None,
  File "/usr/lib/python3.10/runpy.py", line 86, in _run_code
    exec(code, run_globals)
  File "/var/model/lupin/src/ephemera/notebooks/cosa/gsm8k.py", line 233, in <module>
    llm_responses_dict = call_llms(
TypeError: call_llms() got an unexpected keyword argument 'checkpoints_interval'
root@fe0dd39a6dac:/var/model/lupin/src# clear
root@fe0dd39a6dac:/var/model/lupin/src# python3 -m ephemera.notebooks.cosa.gsm8k
Answering 13 questions...
------------------------------------------------------------------------------------------------------------------------
- Question [0] of [13]: Carol and Jennifer are sisters from Los Angeles who love collecting signatures from celebrities. Dur
------------------------------------------------------------------------------------------------------------------------

Instantiating ConfigurationManager() singleton...

Using environment variables to instantiate configuration manager
[0]th arg = [config_path=/src/conf/lupin-app.ini]... done!
[1]th arg = [splainer_path=/src/conf/lupin-app-splainer.ini]... done!
[2]th arg = [config_block_id=Genie+in+the+Box:+Development]... done!

Name value dictionary pairs:

[ config_block_id] = [Genie in the Box: Development]
[     config_path] = [/src/conf/lupin-app.ini]
[   splainer_path] = [/src/conf/lupin-app-splainer.ini]

File exists! [/var/model/lupin/src/conf/lupin-app.ini]
File exists! [/var/model/lupin/src/conf/lupin-app-splainer.ini]

------------------------------------------------------------------------------------------------------------------------
- Initializing configuration_manager [/var/model/lupin/src/conf/lupin-app.ini]
------------------------------------------------------------------------------------------------------------------------
Splainer path [/var/model/lupin/src/conf/lupin-app-splainer.ini]

------------------------------------------------------------------------------------------------------------------------
- Sections, '*' = current block ID
------------------------------------------------------------------------------------------------------------------------

  Genie in the Box: Baseline
* Genie in the Box: Development
  Genie in the Box: Production
  default

------------------------------------------------------------------------------------------------------------------------
- Calculating inheritance... * = parent block
------------------------------------------------------------------------------------------------------------------------

* [Genie in the Box: Development] inherits from [Genie in the Box: Baseline]
Scanning for immutable keys...
Scanning for immutable keys... Done!

------------------------------------------------------------------------------------------------------------------------
- Calculating defaults...
------------------------------------------------------------------------------------------------------------------------

------------------------------------------------------------------------------------------------------------------------
- Loading splainer file [/var/model/lupin/src/conf/lupin-app-splainer.ini]...
------------------------------------------------------------------------------------------------------------------------

¡OJO! MathAgent is using last_question_asked because it wants all the specificity contained within the voice to text transcription
Asking LLM [Groq/llama-3.1-8b-instant]...